Workbook

Sheet Loans
A1: Loan-Level
A2: ID | B2: Repline | C2: Balance | D2: Rate | E2: OrigTerm | F2: Age | G2: IOTerm | H2: WA LTV | I2: WA FICO | J2: SvcFee_Perf | K2: SvcFee_NonPerf | L2: CPR Mult | M2: CDR/DQ Mult | N2: TargetCGL | O2: Price | P2: Spread | Q2: RecoveryLag | R2: Grade | S2: Originator | T2: Recovery | U2: RampLength(Yr) | V2: Type | W2: RemainingTerms | X2: Monthly Pmt | Y2: CGL | Z2: CNL | AA2: Princ WAL | AB2: IRR before svc | AC2: IRR after svc | AD2: Yield Given Price | AE2: Price Given Spread
A3: =IF(loans_raw!A2 = "", "", loans_raw!A2) -> 1 | B3: =IF(loans_raw!B2 = "", "", loans_raw!B2) -> 2018Y | C3: =IF(loans_raw!C2 = "", "", loans_raw!C2) -> 16646668 | D3: =IF(loans_raw!D2 = "", "", loans_raw!D2) -> 0.15760213 | E3: =IF(loans_raw!E2 = "", "", loans_raw!E2) -> 141.47271 | F3: =IF(loans_raw!F2 = "", "", loans_raw!F2) -> 91.069036 | G3: =IF(loans_raw!G2 = "", "", loans_raw!G2) -> 0 | H3: =IF(loans_raw!H2 = "", "", loans_raw!H2) -> 68.162653 | ... AE3: =IF(loans_raw!AE2 = "", "", loans_raw!AE2)
A4: =IF(loans_raw!A3 = "", "", loans_raw!A3) -> 2 | B4: =IF(loans_raw!B3 = "", "", loans_raw!B3) -> 2019Y | C4: =IF(loans_raw!C3 = "", "", loans_raw!C3) -> 38279043 | D4: =IF(loans_raw!D3 = "", "", loans_raw!D3) -> 0.15418358 | E4: =IF(loans_raw!E3 = "", "", loans_raw!E3) -> 139.22585 | F4: =IF(loans_raw!F3 = "", "", loans_raw!F3) -> 80.463526 | G4: =IF(loans_raw!G3 = "", "", loans_raw!G3) -> 0 | H4: =IF(loans_raw!H3 = "", "", loans_raw!H3) -> 6.5080734 | ... AE4: =IF(loans_raw!AE3 = "", "", loans_raw!AE3)
A5: =IF(loans_raw!A4 = "", "", loans_raw!A4) -> 3 | B5: =IF(loans_raw!B4 = "", "", loans_raw!B4) -> 2020Y | C5: =IF(loans_raw!C4 = "", "", loans_raw!C4) -> 53873785 | D5: =IF(loans_raw!D4 = "", "", loans_raw!D4) -> 0.14145943 | E5: =IF(loans_raw!E4 = "", "", loans_raw!E4) -> 141.43722 | F5: =IF(loans_raw!F4 = "", "", loans_raw!F4) -> 68.562882 | G5: =IF(loans_raw!G4 = "", "", loans_raw!G4) -> 0 | H5: =IF(loans_raw!H4 = "", "", loans_raw!H4) -> 91.661202 | ... AE5: =IF(loans_raw!AE4 = "", "", loans_raw!AE4)
A6: =IF(loans_raw!A5 = "", "", loans_raw!A5) -> 4 | B6: =IF(loans_raw!B5 = "", "", loans_raw!B5) -> 2021Y | C6: =IF(loans_raw!C5 = "", "", loans_raw!C5) -> 1.3369645e+08 | D6: =IF(loans_raw!D5 = "", "", loans_raw!D5) -> 0.12735051 | E6: =IF(loans_raw!E5 = "", "", loans_raw!E5) -> 147.40495 | F6: =IF(loans_raw!F5 = "", "", loans_raw!F5) -> 56.222973 | G6: =IF(loans_raw!G5 = "", "", loans_raw!G5) -> 0 | H6: =IF(loans_raw!H5 = "", "", loans_raw!H5) -> 20.688782 | ... AE6: =IF(loans_raw!AE5 = "", "", loans_raw!AE5)
A7: =IF(loans_raw!A6 = "", "", loans_raw!A6) -> 5 | B7: =IF(loans_raw!B6 = "", "", loans_raw!B6) -> 2022Q1 | C7: =IF(loans_raw!C6 = "", "", loans_raw!C6) -> 42691186 | D7: =IF(loans_raw!D6 = "", "", loans_raw!D6) -> 0.13230783 | E7: =IF(loans_raw!E6 = "", "", loans_raw!E6) -> 146.65286 | F7: =IF(loans_raw!F6 = "", "", loans_raw!F6) -> 48.750912 | G7: =IF(loans_raw!G6 = "", "", loans_raw!G6) -> 0 | H7: =IF(loans_raw!H6 = "", "", loans_raw!H6) -> 1.9215388 | ... AE7: =IF(loans_raw!AE6 = "", "", loans_raw!AE6)
A8: =IF(loans_raw!A7 = "", "", loans_raw!A7) -> 6 | B8: =IF(loans_raw!B7 = "", "", loans_raw!B7) -> 2022Q2 | C8: =IF(loans_raw!C7 = "", "", loans_raw!C7) -> 72536049 | D8: =IF(loans_raw!D7 = "", "", loans_raw!D7) -> 0.13257521 | E8: =IF(loans_raw!E7 = "", "", loans_raw!E7) -> 147.87135 | F8: =IF(loans_raw!F7 = "", "", loans_raw!F7) -> 45.901908 | G8: =IF(loans_raw!G7 = "", "", loans_raw!G7) -> 0 | H8: =IF(loans_raw!H7 = "", "", loans_raw!H7) -> 6.9014045 | ... AE8: =IF(loans_raw!AE7 = "", "", loans_raw!AE7)
A9: =IF(loans_raw!A8 = "", "", loans_raw!A8) -> 7 | B9: =IF(loans_raw!B8 = "", "", loans_raw!B8) -> 2022Q3 | C9: =IF(loans_raw!C8 = "", "", loans_raw!C8) -> 65607143 | D9: =IF(loans_raw!D8 = "", "", loans_raw!D8) -> 0.13929328 | E9: =IF(loans_raw!E8 = "", "", loans_raw!E8) -> 145.49735 | F9: =IF(loans_raw!F8 = "", "", loans_raw!F8) -> 43.139982 | G9: =IF(loans_raw!G8 = "", "", loans_raw!G8) -> 0 | H9: =IF(loans_raw!H8 = "", "", loans_raw!H8) -> 2.4759909 | ... AE9: =IF(loans_raw!AE8 = "", "", loans_raw!AE8)
A10: =IF(loans_raw!A9 = "", "", loans_raw!A9) -> 8 | B10: =IF(loans_raw!B9 = "", "", loans_raw!B9) -> 2022Q4 | C10: =IF(loans_raw!C9 = "", "", loans_raw!C9) -> 33160914 | D10: =IF(loans_raw!D9 = "", "", loans_raw!D9) -> 0.15331594 | E10: =IF(loans_raw!E9 = "", "", loans_raw!E9) -> 139.68078 | F10: =IF(loans_raw!F9 = "", "", loans_raw!F9) -> 40.12083 | G10: =IF(loans_raw!G9 = "", "", loans_raw!G9) -> 0 | H10: =IF(loans_raw!H9 = "", "", loans_raw!H9) -> 1.0221334 | ... AE10: =IF(loans_raw!AE9 = "", "", loans_raw!AE9)
A11: =IF(loans_raw!A10 = "", "", loans_raw!A10) -> 9 | B11: =IF(loans_raw!B10 = "", "", loans_raw!B10) -> 2023Q1 | C11: =IF(loans_raw!C10 = "", "", loans_raw!C10) -> 47853870 | D11: =IF(loans_raw!D10 = "", "", loans_raw!D10) -> 0.16122493 | E11: =IF(loans_raw!E10 = "", "", loans_raw!E10) -> 139.44708 | F11: =IF(loans_raw!F10 = "", "", loans_raw!F10) -> 36.742833 | G11: =IF(loans_raw!G10 = "", "", loans_raw!G10) -> 0 | H11: =IF(loans_raw!H10 = "", "", loans_raw!H10) -> 1.0321053 | ... AE11: =IF(loans_raw!AE10 = "", "", loans_raw!AE10)
A12: =IF(loans_raw!A11 = "", "", loans_raw!A11) -> 10 | B12: =IF(loans_raw!B11 = "", "", loans_raw!B11) -> 2023Q2 | C12: =IF(loans_raw!C11 = "", "", loans_raw!C11) -> 1.0426581e+08 | D12: =IF(loans_raw!D11 = "", "", loans_raw!D11) -> 0.15764386 | E12: =IF(loans_raw!E11 = "", "", loans_raw!E11) -> 166.21599 | F12: =IF(loans_raw!F11 = "", "", loans_raw!F11) -> 33.821611 | G12: =IF(loans_raw!G11 = "", "", loans_raw!G11) -> 0 | H12: =IF(loans_raw!H11 = "", "", loans_raw!H11) -> 1.0606238 | ... AE12: =IF(loans_raw!AE11 = "", "", loans_raw!AE11)
A13: =IF(loans_raw!A12 = "", "", loans_raw!A12) -> 11 | B13: =IF(loans_raw!B12 = "", "", loans_raw!B12) -> 2023Q3 | C13: =IF(loans_raw!C12 = "", "", loans_raw!C12) -> 53322098 | D13: =IF(loans_raw!D12 = "", "", loans_raw!D12) -> 0.16331956 | E13: =IF(loans_raw!E12 = "", "", loans_raw!E12) -> 170.18709 | F13: =IF(loans_raw!F12 = "", "", loans_raw!F12) -> 31.099732 | G13: =IF(loans_raw!G12 = "", "", loans_raw!G12) -> 0 | H13: =IF(loans_raw!H12 = "", "", loans_raw!H12) -> 4.5473914 | ... AE13: =IF(loans_raw!AE12 = "", "", loans_raw!AE12)
A14: =IF(loans_raw!A13 = "", "", loans_raw!A13) -> 12 | B14: =IF(loans_raw!B13 = "", "", loans_raw!B13) -> 2023Q4 | C14: =IF(loans_raw!C13 = "", "", loans_raw!C13) -> 36750992 | D14: =IF(loans_raw!D13 = "", "", loans_raw!D13) -> 0.1626543 | E14: =IF(loans_raw!E13 = "", "", loans_raw!E13) -> 167.5215 | F14: =IF(loans_raw!F13 = "", "", loans_raw!F13) -> 28.142694 | G14: =IF(loans_raw!G13 = "", "", loans_raw!G13) -> 0 | H14: =IF(loans_raw!H13 = "", "", loans_raw!H13) -> 17.16956 | ... AE14: =IF(loans_raw!AE13 = "", "", loans_raw!AE13)
... A1002: =IF(loans_raw!A1001 = "", "", loans_raw!A1001) | B1002: =IF(loans_raw!B1001 = "", "", loans_raw!B1001) | C1002: =IF(loans_raw!C1001 = "", "", loans_raw!C1001) | D1002: =IF(loans_raw!D1001 = "", "", loans_raw!D1001) | E1002: =IF(loans_raw!E1001 = "", "", loans_raw!E1001) | F1002: =IF(loans_raw!F1001 = "", "", loans_raw!F1001) | G1002: =IF(loans_raw!G1001 = "", "", loans_raw!G1001) | H1002: =IF(loans_raw!H1001 = "", "", loans_raw!H1001) | ... AE1002: =IF(loans_raw!AE1001 = "", "", loans_raw!AE1001)

Sheet Replines
A1: TOTAL | B1: =SUM(B4:B1003) -> 1.0821619e+09 | C1: =SUM(C4:C1003) -> 1 | D1: =SUMPRODUCT($B$4:$B$1003, D4:D1003) / SUM($B$4:$B$1003) -> 0.14877261 | E1: =SUMPRODUCT($B$4:$B$1003, E4:E1003) / SUM($B$4:$B$1003) -> 0.25671583 | F1: =SUMPRODUCT($B$4:$B$1003, F4:F1003) / SUM($B$4:$B$1003) -> 0.19253688 | G1: =F1/E1 -> 0.75 | H1: =SUMPRODUCT($B$4:$B$1003, H4:H1003) / SUM($B$4:$B$1003) -> 3.3773733 | I1: =F1/H1 -> 0.057007875 | J1: =SUMPRODUCT($B$4:$B$1003, $F$4:$F$1003, J4:J1003) / SUMPRODUCT($B$4:$B$1003, $F$4:$F$1003) -> 0.085683107 | K1: =SUMPRODUCT($B$4:$B$1003, $F$4:$F$1003, K4:K1003) / SUMPRODUCT($B$4:$B$1003, $F$4:$F$1003) -> 0.085683107 | L1: =SUMPRODUCT($B$4:$B$1003, L4:L1003) / SUM($B$4:$B$1003) -> 2.77694 | M1: =SUMPRODUCT($B$4:$B$1003, M4:M1003) / SUM($B$4:$B$1003) -> 100.00766 | N1: =SUMPRODUCT($B$4:$B$1003, N4:N1003) / SUM($B$4:$B$1003) -> 98.619489 | O1: =SUMPRODUCT($B$4:$B$1003, O4:O1003) / SUM($B$4:$B$1003) -> 97.264595 | P1: =SUMPRODUCT($B$4:$B$1003, P4:P1003) / SUM($B$4:$B$1003) -> 104.95074 | Q1: =SUMPRODUCT($B$4:$B$1003, Q4:Q1003) / SUM($B$4:$B$1003) -> 101.99827 | R1: =SUMPRODUCT($B$4:$B$1003, R4:R1003) / SUM($B$4:$B$1003) -> 99.187011
A2: Repline-Level
A3: Repline | B3: UPB | C3: % of Total | D3: WAC | E3: CGL | F3: CNL | G3: Sev | H3: Princ WAL | I3: ANL | J3: IRR before svc | K3: IRR after svc | L3: =IF(reps_raw!L1 = "", "", reps_raw!L1) -> Duration at par | M3: =IF(reps_raw!M1 = "", "", reps_raw!M1) -> Price @450bps to SOFR_1M | N3: =IF(reps_raw!N1 = "", "", reps_raw!N1) -> Price @500bps to SOFR_1M | O3: =IF(reps_raw!O1 = "", "", reps_raw!O1) -> Price @550bps to SOFR_1M | P3: =IF(reps_raw!P1 = "", "", reps_raw!P1) -> Price @ 7.0% Yield | Q3: =IF(reps_raw!Q1 = "", "", reps_raw!Q1) -> Price @ 8.0% Yield | R3: =IF(reps_raw!R1 = "", "", reps_raw!R1) -> Price @ 9.0% Yield
A4: =IF(reps_raw!A2 = "", "", reps_raw!A2) -> 2018Y | B4: =IF(reps_raw!B2 = "", "", reps_raw!B2) -> 16646668 | C4: =IF(reps_raw!C2 = "", "", reps_raw!C2) -> 0.015382789 | D4: =IF(reps_raw!D2 = "", "", reps_raw!D2) -> 0.15760213 | E4: =IF(reps_raw!E2 = "", "", reps_raw!E2) -> 0.13132212 | F4: =IF(reps_raw!F2 = "", "", reps_raw!F2) -> 0.098491587 | G4: =IF(reps_raw!G2 = "", "", reps_raw!G2) -> 0.75 | H4: =IF(reps_raw!H2 = "", "", reps_raw!H2) -> 1.8387946 | ... R4: =IF(reps_raw!R2 = "", "", reps_raw!R2) -> 101.43186
A5: =IF(reps_raw!A3 = "", "", reps_raw!A3) -> 2019Y | B5: =IF(reps_raw!B3 = "", "", reps_raw!B3) -> 38279043 | C5: =IF(reps_raw!C3 = "", "", reps_raw!C3) -> 0.035372751 | D5: =IF(reps_raw!D3 = "", "", reps_raw!D3) -> 0.15418358 | E5: =IF(reps_raw!E3 = "", "", reps_raw!E3) -> 0.11767426 | F5: =IF(reps_raw!F3 = "", "", reps_raw!F3) -> 0.088255696 | G5: =IF(reps_raw!G3 = "", "", reps_raw!G3) -> 0.75 | H5: =IF(reps_raw!H3 = "", "", reps_raw!H3) -> 2.0562003 | ... R5: =IF(reps_raw!R3 = "", "", reps_raw!R3) -> 103.01906
A6: =IF(reps_raw!A4 = "", "", reps_raw!A4) -> 2020Y | B6: =IF(reps_raw!B4 = "", "", reps_raw!B4) -> 53873785 | C6: =IF(reps_raw!C4 = "", "", reps_raw!C4) -> 0.049783481 | D6: =IF(reps_raw!D4 = "", "", reps_raw!D4) -> 0.14145943 | E6: =IF(reps_raw!E4 = "", "", reps_raw!E4) -> 0.13252811 | F6: =IF(reps_raw!F4 = "", "", reps_raw!F4) -> 0.099396083 | G6: =IF(reps_raw!G4 = "", "", reps_raw!G4) -> 0.75 | H6: =IF(reps_raw!H4 = "", "", reps_raw!H4) -> 2.3664576 | ... R6: =IF(reps_raw!R4 = "", "", reps_raw!R4) -> 101.02881
A7: =IF(reps_raw!A5 = "", "", reps_raw!A5) -> 2021Y | B7: =IF(reps_raw!B5 = "", "", reps_raw!B5) -> 1.3369645e+08 | C7: =IF(reps_raw!C5 = "", "", reps_raw!C5) -> 0.1235457 | D7: =IF(reps_raw!D5 = "", "", reps_raw!D5) -> 0.12735051 | E7: =IF(reps_raw!E5 = "", "", reps_raw!E5) -> 0.17983713 | F7: =IF(reps_raw!F5 = "", "", reps_raw!F5) -> 0.13487785 | G7: =IF(reps_raw!G5 = "", "", reps_raw!G5) -> 0.75 | H7: =IF(reps_raw!H5 = "", "", reps_raw!H5) -> 2.8572919 | ... R7: =IF(reps_raw!R5 = "", "", reps_raw!R5) -> 96.557333
A8: =IF(reps_raw!A6 = "", "", reps_raw!A6) -> 2022Q1 | B8: =IF(reps_raw!B6 = "", "", reps_raw!B6) -> 42691186 | C8: =IF(reps_raw!C6 = "", "", reps_raw!C6) -> 0.039449907 | D8: =IF(reps_raw!D6 = "", "", reps_raw!D6) -> 0.13230783 | E8: =IF(reps_raw!E6 = "", "", reps_raw!E6) -> 0.21873941 | F8: =IF(reps_raw!F6 = "", "", reps_raw!F6) -> 0.16405456 | G8: =IF(reps_raw!G6 = "", "", reps_raw!G6) -> 0.75 | H8: =IF(reps_raw!H6 = "", "", reps_raw!H6) -> 3.1405656 | ... R8: =IF(reps_raw!R6 = "", "", reps_raw!R6) -> 96.160491
A9: =IF(reps_raw!A7 = "", "", reps_raw!A7) -> 2022Q2 | B9: =IF(reps_raw!B7 = "", "", reps_raw!B7) -> 72536049 | C9: =IF(reps_raw!C7 = "", "", reps_raw!C7) -> 0.067028834 | D9: =IF(reps_raw!D7 = "", "", reps_raw!D7) -> 0.13257521 | E9: =IF(reps_raw!E7 = "", "", reps_raw!E7) -> 0.26400943 | F9: =IF(reps_raw!F7 = "", "", reps_raw!F7) -> 0.19800707 | G9: =IF(reps_raw!G7 = "", "", reps_raw!G7) -> 0.75 | H9: =IF(reps_raw!H7 = "", "", reps_raw!H7) -> 3.1889191 | ... R9: =IF(reps_raw!R7 = "", "", reps_raw!R7) -> 93.458627
A10: =IF(reps_raw!A8 = "", "", reps_raw!A8) -> 2022Q3 | B10: =IF(reps_raw!B8 = "", "", reps_raw!B8) -> 65607143 | C10: =IF(reps_raw!C8 = "", "", reps_raw!C8) -> 0.060625997 | D10: =IF(reps_raw!D8 = "", "", reps_raw!D8) -> 0.13929328 | E10: =IF(reps_raw!E8 = "", "", reps_raw!E8) -> 0.26292165 | F10: =IF(reps_raw!F8 = "", "", reps_raw!F8) -> 0.19719124 | G10: =IF(reps_raw!G8 = "", "", reps_raw!G8) -> 0.75 | H10: =IF(reps_raw!H8 = "", "", reps_raw!H8) -> 3.0455178 | ... R10: =IF(reps_raw!R8 = "", "", reps_raw!R8) -> 94.672134
A11: =IF(reps_raw!A9 = "", "", reps_raw!A9) -> 2022Q4 | B11: =IF(reps_raw!B9 = "", "", reps_raw!B9) -> 33160914 | C11: =IF(reps_raw!C9 = "", "", reps_raw!C9) -> 0.03064321 | D11: =IF(reps_raw!D9 = "", "", reps_raw!D9) -> 0.15331594 | E11: =IF(reps_raw!E9 = "", "", reps_raw!E9) -> 0.28228138 | F11: =IF(reps_raw!F9 = "", "", reps_raw!F9) -> 0.21171103 | G11: =IF(reps_raw!G9 = "", "", reps_raw!G9) -> 0.75 | H11: =IF(reps_raw!H9 = "", "", reps_raw!H9) -> 3.0434796 | ... R11: =IF(reps_raw!R9 = "", "", reps_raw!R9) -> 96.850028
A12: =IF(reps_raw!A10 = "", "", reps_raw!A10) -> 2023Q1 | B12: =IF(reps_raw!B10 = "", "", reps_raw!B10) -> 47853870 | C12: =IF(reps_raw!C10 = "", "", reps_raw!C10) -> 0.04422062 | D12: =IF(reps_raw!D10 = "", "", reps_raw!D10) -> 0.16122493 | E12: =IF(reps_raw!E10 = "", "", reps_raw!E10) -> 0.26631572 | F12: =IF(reps_raw!F10 = "", "", reps_raw!F10) -> 0.19973679 | G12: =IF(reps_raw!G10 = "", "", reps_raw!G10) -> 0.75 | H12: =IF(reps_raw!H10 = "", "", reps_raw!H10) -> 3.096078 | ... R12: =IF(reps_raw!R10 = "", "", reps_raw!R10) -> 100.15579
A13: =IF(reps_raw!A11 = "", "", reps_raw!A11) -> 2023Q2 | B13: =IF(reps_raw!B11 = "", "", reps_raw!B11) -> 1.0426581e+08 | C13: =IF(reps_raw!C11 = "", "", reps_raw!C11) -> 0.096349549 | D13: =IF(reps_raw!D11 = "", "", reps_raw!D11) -> 0.15764386 | E13: =IF(reps_raw!E11 = "", "", reps_raw!E11) -> 0.31329557 | F13: =IF(reps_raw!F11 = "", "", reps_raw!F11) -> 0.23497168 | G13: =IF(reps_raw!G11 = "", "", reps_raw!G11) -> 0.75 | H13: =IF(reps_raw!H11 = "", "", reps_raw!H11) -> 3.5394688 | ... R13: =IF(reps_raw!R11 = "", "", reps_raw!R11) -> 98.622616
A14: =IF(reps_raw!A12 = "", "", reps_raw!A12) -> 2023Q3 | B14: =IF(reps_raw!B12 = "", "", reps_raw!B12) -> 53322098 | C14: =IF(reps_raw!C12 = "", "", reps_raw!C12) -> 0.04927368 | D14: =IF(reps_raw!D12 = "", "", reps_raw!D12) -> 0.16331956 | E14: =IF(reps_raw!E12 = "", "", reps_raw!E12) -> 0.2103976 | F14: =IF(reps_raw!F12 = "", "", reps_raw!F12) -> 0.1577982 | G14: =IF(reps_raw!G12 = "", "", reps_raw!G12) -> 0.75 | H14: =IF(reps_raw!H12 = "", "", reps_raw!H12) -> 3.7183542 | ... R14: =IF(reps_raw!R12 = "", "", reps_raw!R12) -> 107.62726
A15: =IF(reps_raw!A13 = "", "", reps_raw!A13) -> 2023Q4 | B15: =IF(reps_raw!B13 = "", "", reps_raw!B13) -> 36750992 | C15: =IF(reps_raw!C13 = "", "", reps_raw!C13) -> 0.033960716 | D15: =IF(reps_raw!D13 = "", "", reps_raw!D13) -> 0.1626543 | E15: =IF(reps_raw!E13 = "", "", reps_raw!E13) -> 0.25096241 | F15: =IF(reps_raw!F13 = "", "", reps_raw!F13) -> 0.1882218 | G15: =IF(reps_raw!G13 = "", "", reps_raw!G13) -> 0.75 | H15: =IF(reps_raw!H13 = "", "", reps_raw!H13) -> 3.632101 | ... R15: =IF(reps_raw!R13 = "", "", reps_raw!R13) -> 104.4362
... A1003: =IF(reps_raw!A1001 = "", "", reps_raw!A1001) | B1003: =IF(reps_raw!B1001 = "", "", reps_raw!B1001) | C1003: =IF(reps_raw!C1001 = "", "", reps_raw!C1001) | D1003: =IF(reps_raw!D1001 = "", "", reps_raw!D1001) | E1003: =IF(reps_raw!E1001 = "", "", reps_raw!E1001) | F1003: =IF(reps_raw!F1001 = "", "", reps_raw!F1001) | G1003: =IF(reps_raw!G1001 = "", "", reps_raw!G1001) | H1003: =IF(reps_raw!H1001 = "", "", reps_raw!H1001) | ... R1003: =IF(reps_raw!R1001 = "", "", reps_raw!R1001)

Sheet Total CF
A1: Period | B1: Beg UPB | C1: Delinq UPB | D1: Beg Perf UPB | E1: Delinq Princ | F1: Princ Paid On Delinq Princ | G1: Princ Not Paid On Delinq Princ | H1: Delinq Interest | I1: Int Paid On Delinq Int | J1: Int Not Paid On Delinq Int | K1: Net Interest | L1: Act Amort | M1: Prepayment | N1: Liquidation | O1: Loss | P1: Recovery | Q1: Total UPB Drop | R1: End UPB | S1: Total Cashflow Before Svc | T1: Svc Fee | U1: Total Cashflow | V1: WAC Drift | W1: CPR | X1: CDR | Y1: Sev | Z1: DQ | AA1: DQ Adv
A2: ='CF ALL'!A2 -> 1 | B2: ='CF ALL'!B2 -> 1.0821619e+09 | C2: ='CF ALL'!C2 -> 6799187.6 | D2: ='CF ALL'!D2 -> 1.0753627e+09 | E2: ='CF ALL'!E2 -> 28143.442 | F2: ='CF ALL'!F2 -> 0 | G2: ='CF ALL'!G2 -> 28143.442 | H2: ='CF ALL'!H2 -> 83997.434 | ... AA2: ='CF ALL'!AA2 -> 0
A3: ='CF ALL'!A3 -> 2 | B3: ='CF ALL'!B3 -> 1.0604894e+09 | C3: ='CF ALL'!C3 -> 6687598.5 | D3: ='CF ALL'!D3 -> 1.0538018e+09 | E3: ='CF ALL'!E3 -> 28073.171 | F3: ='CF ALL'!F3 -> 0 | G3: ='CF ALL'!G3 -> 28073.171 | H3: ='CF ALL'!H3 -> 82669.915 | ... AA3: ='CF ALL'!AA3 -> 0
A4: ='CF ALL'!A4 -> 3 | B4: ='CF ALL'!B4 -> 1.0391547e+09 | C4: ='CF ALL'!C4 -> 6553275.2 | D4: ='CF ALL'!D4 -> 1.0326014e+09 | E4: ='CF ALL'!E4 -> 27964.597 | F4: ='CF ALL'!F4 -> 0 | G4: ='CF ALL'!G4 -> 27964.597 | H4: ='CF ALL'!H4 -> 81011.754 | ... AA4: ='CF ALL'!AA4 -> 0
A5: ='CF ALL'!A5 -> 4 | B5: ='CF ALL'!B5 -> 1.018176e+09 | C5: ='CF ALL'!C5 -> 6421210.2 | D5: ='CF ALL'!D5 -> 1.0117547e+09 | E5: ='CF ALL'!E5 -> 27856.428 | F5: ='CF ALL'!F5 -> 0 | G5: ='CF ALL'!G5 -> 27856.428 | H5: ='CF ALL'!H5 -> 79381.794 | ... AA5: ='CF ALL'!AA5 -> 0
A6: ='CF ALL'!A6 -> 5 | B6: ='CF ALL'!B6 -> 9.9754749e+08 | C6: ='CF ALL'!C6 -> 6291366.4 | D6: ='CF ALL'!D6 -> 9.9125612e+08 | E6: ='CF ALL'!E6 -> 27748.708 | F6: ='CF ALL'!F6 -> 0 | G6: ='CF ALL'!G6 -> 27748.708 | H6: ='CF ALL'!H6 -> 77779.399 | ... AA6: ='CF ALL'!AA6 -> 0
A7: ='CF ALL'!A7 -> 6 | B7: ='CF ALL'!B7 -> 9.7726362e+08 | C7: ='CF ALL'!C7 -> 6163707.7 | D7: ='CF ALL'!D7 -> 9.7109991e+08 | E7: ='CF ALL'!E7 -> 27641.481 | F7: ='CF ALL'!F7 -> 0 | G7: ='CF ALL'!G7 -> 27641.481 | H7: ='CF ALL'!H7 -> 76203.949 | ... AA7: ='CF ALL'!AA7 -> 0
A8: ='CF ALL'!A8 -> 7 | B8: ='CF ALL'!B8 -> 9.5731875e+08 | C8: ='CF ALL'!C8 -> 6038198.3 | D8: ='CF ALL'!D8 -> 9.5128055e+08 | E8: ='CF ALL'!E8 -> 27534.661 | F8: ='CF ALL'!F8 -> 0 | G8: ='CF ALL'!G8 -> 27534.661 | H8: ='CF ALL'!H8 -> 74655.318 | ... AA8: ='CF ALL'!AA8 -> 0
A9: ='CF ALL'!A9 -> 8 | B9: ='CF ALL'!B9 -> 9.3770742e+08 | C9: ='CF ALL'!C9 -> 5914803.2 | D9: ='CF ALL'!D9 -> 9.3179262e+08 | E9: ='CF ALL'!E9 -> 27428.36 | F9: ='CF ALL'!F9 -> 0 | G9: ='CF ALL'!G9 -> 27428.36 | H9: ='CF ALL'!H9 -> 73132.651 | ... AA9: ='CF ALL'!AA9 -> 0
A10: ='CF ALL'!A10 -> 9 | B10: ='CF ALL'!B10 -> 9.1842421e+08 | C10: ='CF ALL'!C10 -> 5793487.8 | D10: ='CF ALL'!D10 -> 9.1263072e+08 | E10: ='CF ALL'!E10 -> 27322.493 | F10: ='CF ALL'!F10 -> 0 | G10: ='CF ALL'!G10 -> 27322.493 | H10: ='CF ALL'!H10 -> 71635.816 | ... AA10: ='CF ALL'!AA10 -> 0
A11: ='CF ALL'!A11 -> 10 | B11: ='CF ALL'!B11 -> 8.9946382e+08 | C11: ='CF ALL'!C11 -> 5674218.1 | D11: ='CF ALL'!D11 -> 8.937896e+08 | E11: ='CF ALL'!E11 -> 27217.025 | F11: ='CF ALL'!F11 -> 0 | G11: ='CF ALL'!G11 -> 27217.025 | H11: ='CF ALL'!H11 -> 70164.522 | ... AA11: ='CF ALL'!AA11 -> 0
A12: ='CF ALL'!A12 -> 11 | B12: ='CF ALL'!B12 -> 8.8082103e+08 | C12: ='CF ALL'!C12 -> 5556960.8 | D12: ='CF ALL'!D12 -> 8.7526407e+08 | E12: ='CF ALL'!E12 -> 27112.041 | F12: ='CF ALL'!F12 -> 0 | G12: ='CF ALL'!G12 -> 27112.041 | H12: ='CF ALL'!H12 -> 68718.035 | ... AA12: ='CF ALL'!AA12 -> 0
A13: ='CF ALL'!A13 -> 12 | B13: ='CF ALL'!B13 -> 8.624907e+08 | C13: ='CF ALL'!C13 -> 5441682.9 | D13: ='CF ALL'!D13 -> 8.5704902e+08 | E13: ='CF ALL'!E13 -> 27007.529 | F13: ='CF ALL'!F13 -> 0 | G13: ='CF ALL'!G13 -> 27007.529 | H13: ='CF ALL'!H13 -> 67295.986 | ... AA13: ='CF ALL'!AA13 -> 0
... A361: ='CF ALL'!A361 -> 360 | B361: ='CF ALL'!B361 -> 0 | C361: ='CF ALL'!C361 -> 0 | D361: ='CF ALL'!D361 -> 0 | E361: ='CF ALL'!E361 -> 0 | F361: ='CF ALL'!F361 -> 0 | G361: ='CF ALL'!G361 -> 0 | H361: ='CF ALL'!H361 -> 0 | ... AA361: ='CF ALL'!AA361 -> 0

Sheet loans_raw
A1: ID | B1: Repline | C1: Balance | D1: Rate | E1: OrigTerm | F1: Age | G1: IOTerm | H1: WA LTV | I1: WA FICO | J1: SvcFee_Perf | K1: SvcFee_NonPerf | L1: CPR Mult | M1: CDR/DQ Mult | N1: TargetCGL | O1: Price | P1: Spread | Q1: RecoveryLag | R1: Grade | S1: Originator | T1: Recovery | U1: RampLength(Yr) | V1: Type | W1: RemainingTerms | X1: Monthly Pmt | Y1: CGL | Z1: CNL | AA1: Princ WAL | AB1: IRR before svc | AC1: IRR after svc | AD1: Yield Given Price | AE1: Price Given Spread
A2: 1 | B2: 2018Y | C2: 16646668 | D2: 0.15760213 | E2: 141.47271 | F2: 91.069036 | G2: 0 | H2: 68.162653 | J2: 0 | K2: 0 | L2: 1 | M2: 1 | O2: 100 | S2: GS | T2: 0.25 | U2: 4 | V2: 2018YGS | W2: 50.403678 | X2: 453642.21 | Y2: 0.13132212 | Z2: 0.098491587 | AA2: 1.8387946 | AB2: 0.098513469 | AC2: 0.098513469 | AD2: 0.098513469
A3: 2 | B3: 2019Y | C3: 38279043 | D3: 0.15418358 | E3: 139.22585 | F3: 80.463526 | G3: 0 | H3: 6.5080734 | J3: 0 | K3: 0 | L3: 1 | M3: 1 | O3: 100 | S3: GS | T3: 0.25 | U3: 4 | V3: 2019YGS | W3: 58.76232 | X3: 931977.69 | Y3: 0.11767426 | Z3: 0.088255696 | AA3: 2.0562003 | AB3: 0.10638963 | AC3: 0.10638963 | AD3: 0.10638963
A4: 3 | B4: 2020Y | C4: 53873785 | D4: 0.14145943 | E4: 141.43722 | F4: 68.562882 | G4: 0 | H4: 91.661202 | J4: 0 | K4: 0 | L4: 1 | M4: 1 | O4: 100 | S4: GS | T4: 0.25 | U4: 4 | V4: 2020YGS | W4: 72.874338 | X4: 1105816.8 | Y4: 0.13252811 | Z4: 0.099396083 | AA4: 2.3664576 | AB4: 0.09496559 | AC4: 0.09496559 | AD4: 0.09496559
A5: 4 | B5: 2021Y | C5: 1.3369645e+08 | D5: 0.12735051 | E5: 147.40495 | F5: 56.222973 | G5: 0 | H5: 20.688782 | J5: 0 | K5: 0 | L5: 1 | M5: 1 | O5: 100 | S5: GS | T5: 0.25 | U5: 4 | V5: 2021YGS | W5: 91.181974 | X5: 2295549.3 | Y5: 0.17983713 | Z5: 0.13487785 | AA5: 2.8572919 | AB5: 0.075836268 | AC5: 0.075836268 | AD5: 0.075836268
A6: 5 | B6: 2022Q1 | C6: 42691186 | D6: 0.13230783 | E6: 146.65286 | F6: 48.750912 | G6: 0 | H6: 1.9215388 | J6: 0 | K6: 0 | L6: 1 | M6: 1 | O6: 100 | S6: GS | T6: 0.25 | U6: 4 | V6: 2022Q1GS | W6: 97.901946 | X6: 715130.91 | Y6: 0.21873941 | Z6: 0.16405456 | AA6: 3.1405656 | AB6: 0.075441002 | AC6: 0.075441002 | AD6: 0.075441002
A7: 6 | B7: 2022Q2 | C7: 72536049 | D7: 0.13257521 | E7: 147.87135 | F7: 45.901908 | G7: 0 | H7: 6.9014045 | J7: 0 | K7: 0 | L7: 1 | M7: 1 | O7: 100 | S7: GS | T7: 0.25 | U7: 4 | V7: 2022Q2GS | W7: 101.96945 | X7: 1189259.8 | Y7: 0.26400943 | Z7: 0.19800707 | AA7: 3.1889191 | AB7: 0.065594612 | AC7: 0.065594612 | AD7: 0.065594612
A8: 7 | B8: 2022Q3 | C8: 65607143 | D8: 0.13929328 | E8: 145.49735 | F8: 43.139982 | G8: 0 | H8: 2.4759909 | J8: 0 | K8: 0 | L8: 1 | M8: 1 | O8: 100 | S8: GS | T8: 0.25 | U8: 4 | V8: 2022Q3GS | W8: 102.35737 | X8: 1098731.7 | Y8: 0.26292165 | Z8: 0.19719124 | AA8: 3.0455178 | AB8: 0.06932323 | AC8: 0.06932323 | AD8: 0.06932323
A9: 8 | B9: 2022Q4 | C9: 33160914 | D9: 0.15331594 | E9: 139.68078 | F9: 40.12083 | G9: 0 | H9: 1.0221334 | J9: 0 | K9: 0 | L9: 1 | M9: 1 | O9: 100 | S9: GS | T9: 0.25 | U9: 4 | V9: 2022Q4GS | W9: 99.559947 | X9: 590516.11 | Y9: 0.28228138 | Z9: 0.21171103 | AA9: 3.0434796 | AB9: 0.077814884 | AC9: 0.077814884 | AD9: 0.077814884
A10: 9 | B10: 2023Q1 | C10: 47853870 | D10: 0.16122493 | E10: 139.44708 | F10: 36.742833 | G10: 0 | H10: 1.0321053 | J10: 0 | K10: 0 | L10: 1 | M10: 1 | O10: 100 | S10: GS | T10: 0.25 | U10: 4 | V10: 2023Q1GS | W10: 102.70425 | X10: 861767.18 | Y10: 0.26631572 | Z10: 0.19973679 | AA10: 3.096078 | AB10: 0.090596808 | AC10: 0.090596808 | AD10: 0.090596808
A11: 10 | B11: 2023Q2 | C11: 1.0426581e+08 | D11: 0.15764386 | E11: 166.21599 | F11: 33.821611 | G11: 0 | H11: 1.0606238 | J11: 0 | K11: 0 | L11: 1 | M11: 1 | O11: 100 | S11: GS | T11: 0.25 | U11: 4 | V11: 2023Q2GS | W11: 132.39438 | X11: 1665640.2 | Y11: 0.31329557 | Z11: 0.23497168 | AA11: 3.5394688 | AB11: 0.085223505 | AC11: 0.085223505 | AD11: 0.085223505
A12: 11 | B12: 2023Q3 | C12: 53322098 | D12: 0.16331956 | E12: 170.18709 | F12: 31.099732 | G12: 0 | H12: 4.5473914 | J12: 0 | K12: 0 | L12: 1 | M12: 1 | O12: 100 | S12: GS | T12: 0.25 | U12: 4 | V12: 2023Q3GS | W12: 139.08736 | X12: 856356.11 | Y12: 0.2103976 | Z12: 0.1577982 | AA12: 3.7183542 | AB12: 0.11580229 | AC12: 0.11580229 | AD12: 0.11580229
A13: 12 | B13: 2023Q4 | C13: 36750992 | D13: 0.1626543 | E13: 167.5215 | F13: 28.142694 | G13: 0 | H13: 17.16956 | J13: 0 | K13: 0 | L13: 1 | M13: 1 | O13: 100 | S13: GS | T13: 0.25 | U13: 4 | V13: 2023Q4GS | W13: 139.37881 | X13: 588209.73 | Y13: 0.25096241 | Z13: 0.1882218 | AA13: 3.632101 | AB13: 0.10523069 | AC13: 0.10523069 | AD13: 0.10523069
... A17: 16 | B17: 2024Q4 | C17: 56926793 | D17: 0.16069912 | E17: 174.94427 | F17: 16.067377 | G17: 0 | H17: 1.0164654 | J17: 0 | K17: 0 | L17: 1 | M17: 1 | O17: 100 | S17: GS | T17: 0.25 | U17: 4 | V17: 2024Q4GS | W17: 158.87689 | X17: 867099.08 | Y17: 0.38874849 | Z17: 0.29156137 | AA17: 3.6404832 | AB17: 0.074112306 | AC17: 0.074112306 | AD17: 0.074112306

Sheet reps_raw
A1: Repline | B1: UPB | C1: % of Total | D1: WAC | E1: CGL | F1: CNL | G1: Sev | H1: Princ WAL | I1: ANL | J1: IRR before svc | K1: IRR after svc | L1: Duration at par | M1: Price @450bps to SOFR_1M | N1: Price @500bps to SOFR_1M | O1: Price @550bps to SOFR_1M | P1: Price @ 7.0% Yield | Q1: Price @ 8.0% Yield | R1: Price @ 9.0% Yield
A2: 2018Y | B2: 16646668 | C2: 0.015382789 | D2: 0.15760213 | E2: 0.13132212 | F2: 0.098491587 | G2: 0.75 | H2: 1.8387946 | I2: 0.053563127 | J2: 0.098513469 | K2: 0.098513469 | L2: 1.6636026 | M2: 101.33614 | N2: 100.48888 | O2: 99.652488 | P2: 104.92217 | Q2: 103.15439 | R2: 101.43186
A3: 2019Y | B3: 38279043 | C3: 0.035372751 | D3: 0.15418358 | E3: 0.11767426 | F3: 0.088255696 | G3: 0.75 | H3: 2.0562003 | I3: 0.042921741 | J3: 0.10638963 | K3: 0.10638963 | L3: 1.7995122 | M3: 103.05288 | N3: 102.11149 | O3: 101.18351 | P3: 106.90068 | Q3: 104.93188 | R3: 103.01906
A4: 2020Y | B4: 53873785 | C4: 0.049783481 | D4: 0.14145943 | E4: 0.13252811 | F4: 0.099396083 | G4: 0.75 | H4: 2.3664576 | I4: 0.042002056 | J4: 0.09496559 | K4: 0.09496559 | L4: 2.0549534 | M4: 101.26699 | N4: 100.22051 | O4: 99.191361 | P4: 105.34996 | Q4: 103.15312 | R4: 101.02881
A5: 2021Y | B5: 1.3369645e+08 | C5: 0.1235457 | D5: 0.12735051 | E5: 0.17983713 | F5: 0.13487785 | G5: 0.75 | H5: 2.8572919 | I5: 0.047204786 | J5: 0.075836268 | K5: 0.075836268 | L5: 2.5009592 | M5: 97.087295 | N5: 95.898546 | O5: 94.733409 | P5: 101.47694 | Q5: 98.967484 | R5: 96.557333
A6: 2022Q1 | B6: 42691186 | C6: 0.039449907 | D6: 0.13230783 | E6: 0.21873941 | F6: 0.16405456 | G6: 0.75 | H6: 3.1405656 | I6: 0.052237266 | J6: 0.075441002 | K6: 0.075441002 | L6: 2.7220859 | M6: 96.854161 | N6: 95.565679 | O6: 94.304818 | P6: 101.49878 | Q6: 98.771422 | R6: 96.160491
A7: 2022Q2 | B7: 72536049 | C7: 0.067028834 | D7: 0.13257521 | E7: 0.26400943 | F7: 0.19800707 | G7: 0.75 | H7: 3.1889191 | I7: 0.062092221 | J7: 0.065594612 | K7: 0.065594612 | L7: 2.831038 | M7: 94.179968 | N7: 92.899651 | O7: 91.647535 | P7: 98.765366 | Q7: 96.052503 | R7: 93.458627
A8: 2022Q3 | B8: 65607143 | C8: 0.060625997 | D8: 0.13929328 | E8: 0.26292165 | F8: 0.19719124 | G8: 0.75 | H8: 3.0455178 | I8: 0.064748018 | J8: 0.06932323 | K8: 0.06932323 | L8: 2.6956354 | M8: 95.319282 | N8: 94.077312 | O8: 92.861985 | P8: 99.817859 | Q8: 97.188818 | R8: 94.672134
A9: 2022Q4 | B9: 33160914 | C9: 0.03064321 | D9: 0.15331594 | E9: 0.28228138 | F9: 0.21171103 | G9: 0.75 | H9: 3.0434796 | I9: 0.069562166 | J9: 0.077814884 | K9: 0.077814884 | L9: 2.6539722 | M9: 97.507751 | N9: 96.238148 | O9: 94.995539 | P9: 102.1095 | Q9: 99.42287 | R9: 96.850028
A10: 2023Q1 | B10: 47853870 | C10: 0.04422062 | D10: 0.16122493 | E10: 0.26631572 | F10: 0.19973679 | G10: 0.75 | H10: 3.096078 | I10: 0.064512842 | J10: 0.090596808 | K10: 0.090596808 | L10: 2.6072386 | M10: 100.84761 | N10: 99.529262 | O10: 98.239285 | P10: 105.61825 | Q10: 102.82718 | R10: 100.15579
A11: 2023Q2 | B11: 1.0426581e+08 | C11: 0.096349549 | D11: 0.15764386 | E11: 0.31329557 | F11: 0.23497168 | G11: 0.75 | H11: 3.5394688 | I11: 0.066386141 | J11: 0.085223505 | K11: 0.085223505 | L11: 2.9187808 | M11: 99.54576 | N11: 98.102357 | O11: 96.694768 | P11: 104.61877 | Q11: 101.54468 | R11: 98.622616
A12: 2023Q3 | B12: 53322098 | C12: 0.04927368 | D12: 0.16331956 | E12: 0.2103976 | F12: 0.1577982 | G12: 0.75 | H12: 3.7183542 | I12: 0.042437647 | J12: 0.11580229 | K12: 0.11580229 | L12: 2.7704547 | M12: 108.67406 | N12: 107.07567 | O12: 105.51791 | P12: 114.27075 | Q12: 110.86264 | R12: 107.62726
A13: 2023Q4 | B13: 36750992 | C13: 0.033960716 | D13: 0.1626543 | E13: 0.25096241 | F13: 0.1882218 | G13: 0.75 | H13: 3.632101 | I13: 0.051821742 | J13: 0.10523069 | K13: 0.10523069 | L13: 2.8036231 | M13: 105.42432 | N13: 103.89074 | O13: 102.39584 | P13: 110.80935 | Q13: 107.5406 | R13: 104.4362
... A17: 2024Q4 | B17: 56926793 | C17: 0.052604693 | D17: 0.16069912 | E17: 0.38874849 | F17: 0.29156137 | G17: 0.75 | H17: 3.6404832 | I17: 0.080088644 | J17: 0.074112306 | K17: 0.074112306 | L17: 3.0686284 | M17: 96.278229 | N17: 94.848602 | O17: 93.456572 | P17: 101.27598 | Q17: 98.222148 | R17: 95.328599

Sheet CF ALL
A1: Period | B1: begUPB | C1: begDelinqUPB | D1: begPerfUPB | E1: deinqPrincipal | F1: prinPaidOnDelinqPrin | G1: prinNotPaidOnDelinqPrin | H1: delinqInterest | I1: intPaidOnDelinqInt | J1: intNotPaidOnDelinqInt | K1: netInterest | L1: actAmort | M1: prepayment | N1: liquidation | O1: loss | P1: recovery | Q1: totalUPBDrop | R1: endUPB | S1: totalCashflowBeforeSvc | T1: svcFee | U1: totalCashflow | V1: WAC Drift | W1: CPR | X1: CDR | Y1: Sev | Z1: DQ | AA1: DQ Adv
A2: 1 | B2: 1.0821619e+09 | C2: 6799187.6 | D2: 1.0753627e+09 | E2: 28143.442 | F2: 0 | G2: 28143.442 | H2: 83997.434 | I2: 0 | J2: 83997.434 | K2: 13197521 | L2: 4668557.9 | M2: 10204750 | N2: 6799187.6 | O2: 6799187.6 | P2: 0 | Q2: 21672495 | R2: 1.0604894e+09 | S2: 28070829 | T2: 0 | U2: 28070829 | V2: 14.727761 | W2: 10.791289 | X2: 7.2844013 | Y2: 100 | Z2: 0.62829672 | AA2: 0
A3: 2 | B3: 1.0604894e+09 | C3: 6687598.5 | D3: 1.0538018e+09 | E3: 28073.171 | F3: 0 | G3: 28073.171 | H3: 82669.915 | I3: 0 | J3: 82669.915 | K3: 12937530 | L3: 4649333.6 | M3: 9997790.3 | N3: 6687598.5 | O3: 6652186 | P3: 35412.435 | Q3: 21334722 | R3: 1.0391547e+09 | S3: 27620067 | T3: 0 | U3: 27620067 | V3: 14.733047 | W3: 10.789359 | X3: 7.3103469 | Y3: 99.470476 | Z3: 0.63061437 | AA3: 0
A4: 3 | B4: 1.0391547e+09 | C4: 6553275.2 | D4: 1.0326014e+09 | E4: 27964.597 | F4: 0 | G4: 27964.597 | H4: 81011.754 | I4: 0 | J4: 81011.754 | K4: 12677715 | L4: 4631371.2 | M4: 9794071 | N4: 6553275.2 | O4: 6483031.6 | P4: 70243.678 | Q4: 20978717 | R4: 1.018176e+09 | S4: 27173401 | T4: 0 | U4: 27173401 | V4: 14.733583 | W4: 10.787405 | X4: 7.3105802 | Y4: 98.928113 | Z4: 0.63063521 | AA4: 0
A5: 4 | B5: 1.018176e+09 | C5: 6421210.2 | D5: 1.0117547e+09 | E5: 27856.428 | F5: 0 | G5: 27856.428 | H5: 79381.794 | I5: 0 | J5: 79381.794 | K5: 12422283 | L5: 4613476.4 | M5: 9593776.2 | N5: 6421210.2 | O5: 6316834.8 | P5: 104375.32 | Q5: 20628463 | R5: 9.9754749e+08 | S5: 26733911 | T5: 0 | U5: 26733911 | V5: 14.73419 | W5: 10.785428 | X5: 7.3108375 | Y5: 98.374523 | Z5: 0.6306582 | AA5: 0
A6: 5 | B6: 9.9754749e+08 | C6: 6291366.4 | D6: 9.9125612e+08 | E6: 27748.708 | F6: 0 | G6: 27748.708 | H6: 77779.399 | I6: 0 | J6: 77779.399 | K6: 12171137 | L6: 4595656.5 | M6: 9396850.1 | N6: 6291366.4 | O6: 6153547.3 | P6: 137819.12 | Q6: 20283873 | R6: 9.7726362e+08 | S6: 26301463 | T6: 0 | U6: 26301463 | V6: 14.734837 | W6: 10.783428 | X6: 7.3111196 | Y6: 97.809393 | Z6: 0.6306834 | AA6: 0
A7: 6 | B7: 9.7726362e+08 | C7: 6163707.7 | D7: 9.7109991e+08 | E7: 27641.481 | F7: 0 | G7: 27641.481 | H7: 76203.949 | I7: 0 | J7: 76203.949 | K7: 11924180 | L7: 4577918.5 | M7: 9203237.9 | N7: 6163707.7 | O7: 5993121 | P7: 170586.66 | Q7: 19944864 | R7: 9.5731875e+08 | S7: 25875923 | T7: 0 | U7: 25875923 | V7: 14.735493 | W7: 10.781403 | X7: 7.3114269 | Y7: 97.232402 | Z7: 0.63071085 | AA7: 0
A8: 7 | B8: 9.5731875e+08 | C8: 6038198.3 | D8: 9.5128055e+08 | E8: 27534.661 | F8: 0 | G8: 27534.661 | H8: 74655.318 | I8: 0 | J8: 74655.318 | K8: 11681395 | L8: 4560248.5 | M8: 9012885.7 | N8: 6038198.3 | O8: 5835509 | P8: 202689.3 | Q8: 19611332 | R8: 9.3770742e+08 | S8: 25457218 | T8: 0 | U8: 25457218 | V8: 14.73622 | W8: 10.779352 | X8: 7.3117601 | Y8: 96.643216 | Z8: 0.63074063 | AA8: 0
A9: 8 | B9: 9.3770742e+08 | C9: 5914803.2 | D9: 9.3179262e+08 | E9: 27428.36 | F9: 0 | G9: 27428.36 | H9: 73132.651 | I9: 0 | J9: 73132.651 | K9: 11442647 | L9: 4542664.2 | M9: 8825740.5 | N9: 5914803.2 | O9: 5680665 | P9: 234138.25 | Q9: 19283208 | R9: 9.1842421e+08 | S9: 25045190 | T9: 0 | U9: 25045190 | V9: 14.736937 | W9: 10.777276 | X9: 7.3121201 | Y9: 96.041487 | Z9: 0.63077278 | AA9: 0
A10: 9 | B10: 9.1842421e+08 | C10: 5793487.8 | D10: 9.1263072e+08 | E10: 27322.493 | F10: 0 | G10: 27322.493 | H10: 71635.816 | I10: 0 | J10: 71635.816 | K10: 11207917 | L10: 4525152.6 | M10: 8641750 | N10: 5793487.8 | O10: 5528543.3 | P10: 264944.52 | Q10: 18960390 | R10: 8.9946382e+08 | S10: 24639764 | T10: 0 | U10: 24639764 | V10: 14.737703 | W10: 10.775172 | X10: 7.3125074 | Y10: 95.426856 | Z10: 0.63080739 | AA10: 0
A11: 10 | B11: 8.9946382e+08 | C11: 5674218.1 | D11: 8.937896e+08 | E11: 27217.025 | F11: 0 | G11: 27217.025 | H11: 70164.522 | I11: 0 | J11: 70164.522 | K11: 10977162 | L11: 4507707.6 | M11: 8460863 | N11: 5674218.1 | O11: 5379099.2 | P11: 295118.93 | Q11: 18642789 | R11: 8.8082103e+08 | S11: 24240852 | T11: 0 | U11: 24240852 | V11: 14.73855 | W11: 10.773042 | X11: 7.3129229 | Y11: 94.79895 | Z11: 0.6308445 | AA11: 0
A12: 11 | B12: 8.8082103e+08 | C12: 5556960.8 | D12: 8.7526407e+08 | E12: 27112.041 | F12: 0 | G12: 27112.041 | H12: 68718.035 | I12: 0 | J12: 68718.035 | K12: 10750267 | L12: 4490342.9 | M12: 8283028.9 | N12: 5556960.8 | O12: 5232288.6 | P12: 324672.15 | Q12: 18330333 | R12: 8.624907e+08 | S12: 23848311 | T12: 0 | U12: 23848311 | V12: 14.73941 | W12: 10.770882 | X12: 7.3133672 | Y12: 94.157379 | Z12: 0.6308842 | AA12: 0
A13: 12 | B13: 8.624907e+08 | C13: 5441682.9 | D13: 8.5704902e+08 | E13: 27007.529 | F13: 0 | G13: 27007.529 | H13: 67295.986 | I13: 0 | J13: 67295.986 | K13: 10527176 | L13: 4473056.7 | M13: 8108198 | N13: 5441682.9 | O13: 5088068.2 | P13: 353614.65 | Q13: 18022938 | R13: 8.4446776e+08 | S13: 23462045 | T13: 0 | U13: 23462045 | V13: 14.740293 | W13: 10.768694 | X13: 7.3138413 | Y13: 93.501741 | Z13: 0.63092656 | AA13: 0
... A160: 159 | B160: 41106.277 | C160: 366.19818 | D160: 40740.078 | E160: 362.93587 | F160: 0 | G160: 362.93587 | H160: 4.8599178 | I160: 0 | J160: 4.8599178 | K160: 540.6729 | L160: 40377.143 | M160: 3.4654593 | N160: 725.66859 | O160: -25653.383 | P160: 26379.051 | Q160: 41106.277 | R160: 0 | S160: 67300.332 | T160: 0 | U160: 67300.332 | V160: 15.925534 | W160: 5.5566572 | X160: 19.243672 | Y160: -3535.1375 | Z160: 0.89085708 | AA160: 0
A161: 160 | B161: 0 | C161: 0 | D161: 0 | E161: 0 | F161: 0 | G161: 0 | H161: 0 | I161: 0 | J161: 0 | K161: 0 | L161: 0 | M161: 0 | N161: 0 | O161: -24915.335 | P161: 24915.335 | Q161: 0 | R161: 0 | S161: 24915.335 | T161: 0 | U161: 24915.335 | Y161: -inf
A162: 161 | B162: 0 | C162: 0 | D162: 0 | E162: 0 | F162: 0 | G162: 0 | H162: 0 | I162: 0 | J162: 0 | K162: 0 | L162: 0 | M162: 0 | N162: 0 | O162: -23501.517 | P162: 23501.517 | Q162: 0 | R162: 0 | S162: 23501.517 | T162: 0 | U162: 23501.517 | Y162: -inf
A163: 162 | B163: 0 | C163: 0 | D163: 0 | E163: 0 | F163: 0 | G163: 0 | H163: 0 | I163: 0 | J163: 0 | K163: 0 | L163: 0 | M163: 0 | N163: 0 | O163: -22140.415 | P163: 22140.415 | Q163: 0 | R163: 0 | S163: 22140.415 | T163: 0 | U163: 22140.415 | Y163: -inf
A164: 163 | B164: 0 | C164: 0 | D164: 0 | E164: 0 | F164: 0 | G164: 0 | H164: 0 | I164: 0 | J164: 0 | K164: 0 | L164: 0 | M164: 0 | N164: 0 | O164: -20831.081 | P164: 20831.081 | Q164: 0 | R164: 0 | S164: 20831.081 | T164: 0 | U164: 20831.081 | Y164: -inf
A165: 164 | B165: 0 | C165: 0 | D165: 0 | E165: 0 | F165: 0 | G165: 0 | H165: 0 | I165: 0 | J165: 0 | K165: 0 | L165: 0 | M165: 0 | N165: 0 | O165: -19572.586 | P165: 19572.586 | Q165: 0 | R165: 0 | S165: 19572.586 | T165: 0 | U165: 19572.586 | Y165: -inf
A166: 165 | B166: 0 | C166: 0 | D166: 0 | E166: 0 | F166: 0 | G166: 0 | H166: 0 | I166: 0 | J166: 0 | K166: 0 | L166: 0 | M166: 0 | N166: 0 | O166: -18364.013 | P166: 18364.013 | Q166: 0 | R166: 0 | S166: 18364.013 | T166: 0 | U166: 18364.013 | Y166: -inf
A167: 166 | B167: 0 | C167: 0 | D167: 0 | E167: 0 | F167: 0 | G167: 0 | H167: 0 | I167: 0 | J167: 0 | K167: 0 | L167: 0 | M167: 0 | N167: 0 | O167: -17204.464 | P167: 17204.464 | Q167: 0 | R167: 0 | S167: 17204.464 | T167: 0 | U167: 17204.464 | Y167: -inf
A168: 167 | B168: 0 | C168: 0 | D168: 0 | E168: 0 | F168: 0 | G168: 0 | H168: 0 | I168: 0 | J168: 0 | K168: 0 | L168: 0 | M168: 0 | N168: 0 | O168: -16093.054 | P168: 16093.054 | Q168: 0 | R168: 0 | S168: 16093.054 | T168: 0 | U168: 16093.054 | Y168: -inf
A169: 168 | B169: 0 | C169: 0 | D169: 0 | E169: 0 | F169: 0 | G169: 0 | H169: 0 | I169: 0 | J169: 0 | K169: 0 | L169: 0 | M169: 0 | N169: 0 | O169: -15028.915 | P169: 15028.915 | Q169: 0 | R169: 0 | S169: 15028.915 | T169: 0 | U169: 15028.915 | Y169: -inf
A170: 169 | B170: 0 | C170: 0 | D170: 0 | E170: 0 | F170: 0 | G170: 0 | H170: 0 | I170: 0 | J170: 0 | K170: 0 | L170: 0 | M170: 0 | N170: 0 | O170: -14011.192 | P170: 14011.192 | Q170: 0 | R170: 0 | S170: 14011.192 | T170: 0 | U170: 14011.192 | Y170: -inf
A171: 170 | B171: 0 | C171: 0 | D171: 0 | E171: 0 | F171: 0 | G171: 0 | H171: 0 | I171: 0 | J171: 0 | K171: 0 | L171: 0 | M171: 0 | N171: 0 | O171: -13039.047 | P171: 13039.047 | Q171: 0 | R171: 0 | S171: 13039.047 | T171: 0 | U171: 13039.047 | Y171: -inf
A172: 171 | B172: 0 | C172: 0 | D172: 0 | E172: 0 | F172: 0 | G172: 0 | H172: 0 | I172: 0 | J172: 0 | K172: 0 | L172: 0 | M172: 0 | N172: 0 | O172: -12111.654 | P172: 12111.654 | Q172: 0 | R172: 0 | S172: 12111.654 | T172: 0 | U172: 12111.654 | Y172: -inf
... A208: 207 | B208: 0 | C208: 0 | D208: 0 | E208: 0 | F208: 0 | G208: 0 | H208: 0 | I208: 0 | J208: 0 | K208: 0 | L208: 0 | M208: 0 | N208: 0 | O208: -3.7795239 | P208: 3.7795239 | Q208: 0 | R208: 0 | S208: 3.7795239 | T208: 0 | U208: 3.7795239 | Y208: -inf
A209: 208 | B209: 0 | C209: 0 | D209: 0 | E209: 0 | F209: 0 | G209: 0 | H209: 0 | I209: 0 | J209: 0 | K209: 0 | L209: 0 | M209: 0 | N209: 0 | O209: 0 | P209: 0 | Q209: 0 | R209: 0 | S209: 0 | T209: 0 | U209: 0
A210: 209 | B210: 0 | C210: 0 | D210: 0 | E210: 0 | F210: 0 | G210: 0 | H210: 0 | I210: 0 | J210: 0 | K210: 0 | L210: 0 | M210: 0 | N210: 0 | O210: 0 | P210: 0 | Q210: 0 | R210: 0 | S210: 0 | T210: 0 | U210: 0
A211: 210 | B211: 0 | C211: 0 | D211: 0 | E211: 0 | F211: 0 | G211: 0 | H211: 0 | I211: 0 | J211: 0 | K211: 0 | L211: 0 | M211: 0 | N211: 0 | O211: 0 | P211: 0 | Q211: 0 | R211: 0 | S211: 0 | T211: 0 | U211: 0
A212: 211 | B212: 0 | C212: 0 | D212: 0 | E212: 0 | F212: 0 | G212: 0 | H212: 0 | I212: 0 | J212: 0 | K212: 0 | L212: 0 | M212: 0 | N212: 0 | O212: 0 | P212: 0 | Q212: 0 | R212: 0 | S212: 0 | T212: 0 | U212: 0
A213: 212 | B213: 0 | C213: 0 | D213: 0 | E213: 0 | F213: 0 | G213: 0 | H213: 0 | I213: 0 | J213: 0 | K213: 0 | L213: 0 | M213: 0 | N213: 0 | O213: 0 | P213: 0 | Q213: 0 | R213: 0 | S213: 0 | T213: 0 | U213: 0
A214: 213 | B214: 0 | C214: 0 | D214: 0 | E214: 0 | F214: 0 | G214: 0 | H214: 0 | I214: 0 | J214: 0 | K214: 0 | L214: 0 | M214: 0 | N214: 0 | O214: 0 | P214: 0 | Q214: 0 | R214: 0 | S214: 0 | T214: 0 | U214: 0
A215: 214 | B215: 0 | C215: 0 | D215: 0 | E215: 0 | F215: 0 | G215: 0 | H215: 0 | I215: 0 | J215: 0 | K215: 0 | L215: 0 | M215: 0 | N215: 0 | O215: 0 | P215: 0 | Q215: 0 | R215: 0 | S215: 0 | T215: 0 | U215: 0
A216: 215 | B216: 0 | C216: 0 | D216: 0 | E216: 0 | F216: 0 | G216: 0 | H216: 0 | I216: 0 | J216: 0 | K216: 0 | L216: 0 | M216: 0 | N216: 0 | O216: 0 | P216: 0 | Q216: 0 | R216: 0 | S216: 0 | T216: 0 | U216: 0
A217: 216 | B217: 0 | C217: 0 | D217: 0 | E217: 0 | F217: 0 | G217: 0 | H217: 0 | I217: 0 | J217: 0 | K217: 0 | L217: 0 | M217: 0 | N217: 0 | O217: 0 | P217: 0 | Q217: 0 | R217: 0 | S217: 0 | T217: 0 | U217: 0
A218: 217 | B218: 0 | C218: 0 | D218: 0 | E218: 0 | F218: 0 | G218: 0 | H218: 0 | I218: 0 | J218: 0 | K218: 0 | L218: 0 | M218: 0 | N218: 0 | O218: 0 | P218: 0 | Q218: 0 | R218: 0 | S218: 0 | T218: 0 | U218: 0
A219: 218 | B219: 0 | C219: 0 | D219: 0 | E219: 0 | F219: 0 | G219: 0 | H219: 0 | I219: 0 | J219: 0 | K219: 0 | L219: 0 | M219: 0 | N219: 0 | O219: 0 | P219: 0 | Q219: 0 | R219: 0 | S219: 0 | T219: 0 | U219: 0
A220: 219 | B220: 0 | C220: 0 | D220: 0 | E220: 0 | F220: 0 | G220: 0 | H220: 0 | I220: 0 | J220: 0 | K220: 0 | L220: 0 | M220: 0 | N220: 0 | O220: 0 | P220: 0 | Q220: 0 | R220: 0 | S220: 0 | T220: 0 | U220: 0
... A361: 360 | B361: 0 | C361: 0 | D361: 0 | E361: 0 | F361: 0 | G361: 0 | H361: 0 | I361: 0 | J361: 0 | K361: 0 | L361: 0 | M361: 0 | N361: 0 | O361: 0 | P361: 0 | Q361: 0 | R361: 0 | S361: 0 | T361: 0 | U361: 0

Sheet 2018Y
A1: Period | B1: begUPB | C1: begDelinqUPB | D1: begPerfUPB | E1: deinqPrincipal | F1: prinPaidOnDelinqPrin | G1: prinNotPaidOnDelinqPrin | H1: delinqInterest | I1: intPaidOnDelinqInt | J1: intNotPaidOnDelinqInt | K1: netInterest | L1: actAmort | M1: prepayment | N1: liquidation | O1: loss | P1: recovery | Q1: totalUPBDrop | R1: endUPB | S1: totalCashflowBeforeSvc | T1: svcFee | U1: totalCashflow
A2: 1 | B2: 16646668 | C2: 99049.278 | D2: 16547619 | E2: 1394.7267 | F2: 0 | G2: 1394.7267 | H2: 1288.5249 | I2: 0 | J2: 1288.5249 | K2: 215266.77 | L2: 233009.33 | M2: 158613.96 | N2: 99049.278 | O2: 99049.278 | P2: 0 | Q2: 490672.56 | R2: 16155995 | S2: 606890.05 | T2: 0 | U2: 606890.05
A3: 2 | B3: 16155995 | C3: 96129.729 | D3: 16059866 | E3: 1390.7855 | F3: 0 | G3: 1390.7855 | H3: 1250.9175 | I3: 0 | J3: 1250.9175 | K3: 208983.92 | L3: 232350.9 | M3: 153878.32 | N3: 96129.729 | O3: 95613.848 | P3: 515.88166 | Q3: 482358.95 | R3: 15673636 | S3: 595729.02 | T3: 0 | U3: 595729.02
A4: 3 | B4: 15673636 | C4: 93259.647 | D4: 15580377 | E4: 1387.0093 | F4: 0 | G4: 1387.0093 | H4: 1213.5624 | I4: 0 | J4: 1213.5624 | K4: 202743.21 | L4: 231720.02 | M4: 149222.77 | N4: 93259.647 | O4: 92243.09 | P4: 1016.5573 | Q4: 474202.43 | R4: 15199434 | S4: 584702.55 | T4: 0 | U4: 584702.55
A5: 4 | B5: 15199434 | C5: 90438.097 | D5: 15108996 | E5: 1383.2453 | F5: 0 | G5: 1383.2453 | H5: 1176.8426 | I5: 0 | J5: 1176.8426 | K5: 196608.62 | L5: 231091.19 | M5: 144646.02 | N5: 90438.097 | O5: 88935.812 | P5: 1502.2847 | Q5: 466175.31 | R5: 14733259 | S5: 573848.11 | T5: 0 | U5: 573848.11
A6: 5 | B6: 14733259 | C6: 87664.309 | D6: 14645594 | E6: 1379.4947 | F6: 0 | G6: 1379.4947 | H6: 1140.7453 | I6: 0 | J6: 1140.7453 | K6: 190578.05 | L6: 230464.6 | M6: 140146.82 | N6: 87664.309 | O6: 85690.993 | P6: 1973.3164 | Q6: 458275.73 | R6: 14274983 | S6: 563162.79 | T6: 0 | U6: 563162.79
A7: 6 | B7: 14274983 | C7: 84937.524 | D7: 14190045 | E7: 1375.7585 | F7: 0 | G7: 1375.7585 | H7: 1105.2585 | I7: 0 | J7: 1105.2585 | K7: 184649.46 | L7: 229840.42 | M7: 135723.95 | N7: 84937.524 | O7: 82507.623 | P7: 2429.9014 | Q7: 450501.89 | R7: 13824481 | S7: 552643.73 | T7: 0 | U7: 552643.73
A8: 7 | B8: 13824481 | C8: 82256.995 | D8: 13742224 | E8: 1372.0352 | F8: 0 | G8: 1372.0352 | H8: 1070.3766 | I8: 0 | J8: 1070.3766 | K8: 178821.94 | L8: 229218.38 | M8: 131376.18 | N8: 82256.995 | O8: 79384.71 | P8: 2872.2843 | Q8: 442851.55 | R8: 13381630 | S8: 542288.78 | T8: 0 | U8: 542288.78
A9: 8 | B9: 13381630 | C9: 79621.985 | D9: 13302008 | E9: 1368.327 | F9: 0 | G9: 1368.327 | H9: 1036.0845 | I9: 0 | J9: 1036.0845 | K9: 173092.94 | L9: 228598.87 | M9: 127102.33 | N9: 79621.985 | O9: 76321.279 | P9: 3300.7061 | Q9: 435323.19 | R9: 12946306 | S9: 532094.85 | T9: 0 | U9: 532094.85
A10: 9 | B10: 12946306 | C10: 77031.77 | D10: 12869275 | E10: 1364.6325 | F10: 0 | G10: 1364.6325 | H10: 1002.3767 | I10: 0 | J10: 1002.3767 | K10: 167461.57 | L10: 227981.66 | M10: 122901.21 | N10: 77031.77 | O10: 73316.366 | P10: 3715.404 | Q10: 427914.64 | R10: 12518392 | S10: 522059.84 | T10: 0 | U10: 522059.84
A11: 10 | B11: 12518392 | C11: 74485.637 | D11: 12443906 | E11: 1360.9513 | F11: 0 | G11: 1360.9513 | H11: 969.24562 | I11: 0 | J11: 969.24562 | K11: 161926.54 | L11: 227366.65 | M11: 118771.67 | N11: 74485.637 | O11: 70369.026 | P11: 4116.6111 | Q11: 420623.96 | R11: 12097768 | S11: 512181.47 | T11: 0 | U11: 512181.47
A12: 11 | B12: 12097768 | C12: 71982.884 | D12: 12025785 | E12: 1357.2851 | F12: 0 | G12: 1357.2851 | H12: 936.67788 | I12: 0 | J12: 936.67788 | K12: 156485.63 | L12: 226754.16 | M12: 114712.56 | N12: 71982.884 | O12: 67478.327 | P12: 4504.5571 | Q12: 413449.61 | R12: 11684318 | S12: 502456.91 | T12: 0 | U12: 502456.91
A13: 12 | B13: 11684318 | C13: 69522.819 | D13: 11614795 | E13: 1353.634 | F13: 0 | G13: 1353.634 | H13: 904.66501 | I13: 0 | J13: 904.66501 | K13: 151137.41 | L13: 226144.19 | M13: 110722.77 | N13: 69522.819 | O13: 64643.351 | P13: 4879.468 | Q13: 406389.77 | R13: 11277928 | S13: 492883.83 | T13: 0 | U13: 492883.83
... A361: 360 | B361: 0 | C361: 0 | D361: 0 | E361: 0 | F361: 0 | G361: 0 | H361: 0 | I361: 0 | J361: 0 | K361: 0 | L361: 0 | M361: 0 | N361: 0 | O361: 0 | P361: 0 | Q361: 0 | R361: 0 | S361: 0 | T361: 0 | U361: 0

Sheet 2019Y
A1: Period | B1: begUPB | C1: begDelinqUPB | D1: begPerfUPB | E1: deinqPrincipal | F1: prinPaidOnDelinqPrin | G1: prinNotPaidOnDelinqPrin | H1: delinqInterest | I1: intPaidOnDelinqInt | J1: intNotPaidOnDelinqInt | K1: netInterest | L1: actAmort | M1: prepayment | N1: liquidation | O1: loss | P1: recovery | Q1: totalUPBDrop | R1: endUPB | S1: totalCashflowBeforeSvc | T1: svcFee | U1: totalCashflow
A2: 1 | B2: 38279043 | C2: 182503.01 | D2: 38096540 | E2: 2096.8383 | F2: 0 | G2: 2096.8383 | H2: 2322.1772 | I2: 0 | J2: 2322.1772 | K2: 484742.23 | L2: 437703.92 | M2: 431612.42 | N2: 182503.01 | O2: 182503.01 | P2: 0 | Q2: 1051819.4 | R2: 37227223 | S2: 1354058.6 | T2: 0 | U2: 1354058.6
A3: 2 | B3: 37227223 | C3: 177488.25 | D3: 37049735 | E3: 2089.0338 | F3: 0 | G3: 2089.0338 | H3: 2259.0576 | I3: 0 | J3: 2259.0576 | K3: 471566.34 | L3: 436074.77 | M3: 419633.53 | N3: 177488.25 | O3: 176537.71 | P3: 950.53652 | Q3: 1033196.6 | R3: 36194027 | S3: 1328225.2 | T3: 0 | U3: 1328225.2
A4: 3 | B4: 36194027 | C4: 172562.28 | D4: 36021465 | E4: 2081.5282 | F4: 0 | G4: 2081.5282 | H4: 2196.3467 | I4: 0 | J4: 2196.3467 | K4: 458475.77 | L4: 434508.01 | M4: 407866.35 | N4: 172562.28 | O4: 170687.33 | P4: 1874.9545 | Q4: 1014936.6 | R4: 35179090 | S4: 1302725.1 | T4: 0 | U4: 1302725.1
A5: 4 | B5: 35179090 | C5: 167723.37 | D5: 35011367 | E5: 2074.05 | F5: 0 | G5: 2074.05 | H5: 2134.7507 | I5: 0 | J5: 2134.7507 | K5: 445617.93 | L5: 432946.98 | M5: 396307.39 | N5: 167723.37 | O5: 164949.65 | P5: 2773.7164 | Q5: 996977.74 | R5: 34182112 | S5: 1277646 | T5: 0 | U5: 1277646
A6: 5 | B6: 34182112 | C6: 162970.07 | D6: 34019142 | E6: 2066.601 | F6: 0 | G6: 2066.601 | H6: 2074.2465 | I6: 0 | J6: 2074.2465 | K6: 432988 | L6: 431392.05 | M6: 384953.21 | N6: 162970.07 | O6: 159322.8 | P6: 3647.2756 | Q6: 979315.33 | R6: 33202797 | S6: 1252980.5 | T6: 0 | U6: 1252980.5
A7: 6 | B7: 33202797 | C7: 158300.99 | D7: 33044496 | E7: 2059.1828 | F7: 0 | G7: 2059.1828 | H7: 2014.8117 | I7: 0 | J7: 2014.8117 | K7: 420581.31 | L7: 429843.54 | M7: 373800.42 | N7: 158300.99 | O7: 153804.91 | P7: 4496.078 | Q7: 961944.95 | R7: 32240852 | S7: 1228721.3 | T7: 0 | U7: 1228721.3
A8: 7 | B8: 32240852 | C8: 153714.73 | D8: 32087137 | E8: 2051.7924 | F8: 0 | G8: 2051.7924 | H8: 1956.4368 | I8: 0 | J8: 1956.4368 | K8: 408395.85 | L8: 428300.84 | M8: 362845.69 | N8: 153714.73 | O8: 148394.16 | P8: 5320.5624 | Q8: 944861.26 | R8: 31295991 | S8: 1204862.9 | T8: 0 | U8: 1204862.9
A9: 8 | B9: 31295991 | C9: 149209.91 | D9: 31146781 | E9: 2044.4339 | F9: 0 | G9: 2044.4339 | H9: 1899.0936 | I9: 0 | J9: 1899.0936 | K9: 396425.77 | L9: 426764.77 | M9: 352085.76 | N9: 149209.91 | O9: 143088.75 | P9: 6121.1599 | Q9: 928060.44 | R9: 30367930 | S9: 1181397.5 | T9: 0 | U9: 1181397.5
A10: 9 | B10: 30367930 | C10: 144785.2 | D10: 30223145 | E10: 2037.1042 | F10: 0 | G10: 2037.1042 | H10: 1842.7726 | I10: 0 | J10: 1842.7726 | K10: 384669.05 | L10: 425234.75 | M10: 341517.39 | N10: 144785.2 | O10: 137886.9 | P10: 6898.2949 | Q10: 911537.34 | R10: 29456393 | S10: 1158319.5 | T10: 0 | U10: 1158319.5
A11: 10 | B11: 29456393 | C11: 140439.26 | D11: 29315954 | E11: 2029.8023 | F11: 0 | G11: 2029.8023 | H11: 1787.4601 | I11: 0 | J11: 1787.4601 | K11: 373122.86 | L11: 423710.51 | M11: 331137.43 | N11: 140439.26 | O11: 132786.88 | P11: 7652.3844 | Q11: 895287.2 | R11: 28561106 | S11: 1135623.2 | T11: 0 | U11: 1135623.2
A12: 11 | B12: 28561106 | C12: 136170.8 | D12: 28424935 | E12: 2022.5312 | F12: 0 | G12: 2022.5312 | H12: 1733.1315 | I12: 0 | J12: 1733.1315 | K12: 361782.05 | L12: 422192.7 | M12: 320942.75 | N12: 136170.8 | O12: 127786.96 | P12: 8383.8389 | Q12: 879306.25 | R12: 27681800 | S12: 1113301.3 | T12: 0 | U12: 1113301.3
A13: 12 | B13: 27681800 | C13: 131978.53 | D13: 27549821 | E13: 2015.2906 | F13: 0 | G13: 2015.2906 | H13: 1679.7715 | I13: 0 | J13: 1679.7715 | K13: 350643.43 | L13: 420681.26 | M13: 310930.29 | N13: 131978.53 | O13: 122885.47 | P13: 9093.0618 | Q13: 863590.08 | R13: 26818210 | S13: 1091348 | T13: 0 | U13: 1091348
... A361: 360 | B361: 0 | C361: 0 | D361: 0 | E361: 0 | F361: 0 | G361: 0 | H361: 0 | I361: 0 | J361: 0 | K361: 0 | L361: 0 | M361: 0 | N361: 0 | O361: 0 | P361: 0 | Q361: 0 | R361: 0 | S361: 0 | T361: 0 | U361: 0

Sheet 2020Y
A1: Period | B1: begUPB | C1: begDelinqUPB | D1: begPerfUPB | E1: deinqPrincipal | F1: prinPaidOnDelinqPrin | G1: prinNotPaidOnDelinqPrin | H1: delinqInterest | I1: intPaidOnDelinqInt | J1: intNotPaidOnDelinqInt | K1: netInterest | L1: actAmort | M1: prepayment | N1: liquidation | O1: loss | P1: recovery | Q1: totalUPBDrop | R1: endUPB | S1: totalCashflowBeforeSvc | T1: svcFee | U1: totalCashflow
A2: 1 | B2: 53873785 | C2: 251377.22 | D2: 53622408 | E2: 2197.3045 | F2: 0 | G2: 2197.3045 | H2: 2931.9893 | I2: 0 | J2: 2931.9893 | K2: 625435.84 | L2: 468716.92 | M2: 653771.47 | N2: 251377.22 | O2: 251377.22 | P2: 0 | Q2: 1373865.6 | R2: 52499920 | S2: 1747924.2 | T2: 0 | U2: 1747924.2
A3: 2 | B3: 52499920 | C3: 244966.71 | D3: 52254953 | E3: 2185.0993 | F3: 0 | G3: 2185.0993 | H3: 2858.1691 | I3: 0 | J3: 2858.1691 | K3: 609688.93 | L3: 466113.37 | M3: 636984.28 | N3: 244966.71 | O3: 243657.46 | P3: 1309.2564 | Q3: 1348064.4 | R3: 51151855 | S3: 1714095.8 | T3: 0 | U3: 1714095.8
A4: 3 | B4: 51151855 | C4: 238676.59 | D4: 50913179 | E4: 2173.3151 | F4: 0 | G4: 2173.3151 | H4: 2784.76 | I4: 0 | J4: 2784.76 | K4: 594029.69 | L4: 463599.63 | M4: 620511.85 | N4: 238676.59 | O4: 236091.47 | P4: 2585.1247 | Q4: 1322788.1 | R4: 49829067 | S4: 1680726.3 | T4: 0 | U4: 1680726.3
A5: 4 | B5: 49829067 | C5: 232504.41 | D5: 49596563 | E5: 2161.5931 | F5: 0 | G5: 2161.5931 | H5: 2712.7362 | I5: 0 | J5: 2712.7362 | K5: 578665.99 | L5: 461099.16 | M5: 604348.69 | N5: 232504.41 | O5: 228676.18 | P5: 3828.2319 | Q5: 1297952.3 | R5: 48531115 | S5: 1647942.1 | T5: 0 | U5: 1647942.1
A6: 5 | B6: 48531115 | C6: 226448.11 | D6: 48304667 | E6: 2149.9353 | F6: 0 | G6: 2149.9353 | H6: 2642.0674 | I6: 0 | J6: 2642.0674 | K6: 563591.29 | L6: 458612.39 | M6: 588489.42 | N6: 226448.11 | O6: 221408.92 | P6: 5039.1924 | Q6: 1273549.9 | R6: 47257565 | S6: 1615732.3 | T6: 0 | U6: 1615732.3
A7: 6 | B7: 47257565 | C7: 220505.68 | D7: 47037060 | E7: 2138.3436 | F7: 0 | G7: 2138.3436 | H7: 2572.7237 | I7: 0 | J7: 2572.7237 | K7: 548799.28 | L7: 456139.72 | M7: 572928.71 | N7: 220505.68 | O7: 214287.07 | P7: 6218.6096 | Q7: 1249574.1 | R7: 46007991 | S7: 1584086.3 | T7: 0 | U7: 1584086.3
A8: 7 | B8: 46007991 | C8: 214675.12 | D8: 45793316 | E8: 2126.8137 | F8: 0 | G8: 2126.8137 | H8: 2504.6932 | I8: 0 | J8: 2504.6932 | K8: 534287.4 | L8: 453680.21 | M8: 557661.35 | N8: 214675.12 | O8: 207308.04 | P8: 7367.0767 | Q8: 1226016.7 | R8: 44781974 | S8: 1552996 | T8: 0 | U8: 1552996
A9: 8 | B9: 44781974 | C9: 208954.47 | D9: 44573020 | E9: 2115.3505 | F9: 0 | G9: 2115.3505 | H9: 2437.9384 | I9: 0 | J9: 2437.9384 | K9: 520047.61 | L9: 451234.95 | M9: 542682.22 | N9: 208954.47 | O9: 200469.3 | P9: 8485.1763 | Q9: 1202871.6 | R9: 43579103 | S9: 1522450 | T9: 0 | U9: 1522450
A10: 9 | B10: 43579103 | C10: 203341.83 | D10: 43375761 | E10: 2103.9501 | F10: 0 | G10: 2103.9501 | H10: 2372.4472 | I10: 0 | J10: 2372.4472 | K10: 506077.39 | L10: 448803.07 | M10: 527986.27 | N10: 203341.83 | O10: 193768.35 | P10: 9573.4808 | Q10: 1180131.2 | R10: 42398972 | S10: 1492440.2 | T10: 0 | U10: 1492440.2
A11: 10 | B11: 42398972 | C11: 197835.29 | D11: 42201136 | E11: 2092.6102 | F11: 0 | G11: 2092.6102 | H11: 2308.2022 | I11: 0 | J11: 2308.2022 | K11: 492373 | L11: 446384.12 | M11: 513568.56 | N11: 197835.29 | O11: 187202.73 | P11: 10632.553 | Q11: 1157788 | R11: 41241184 | S11: 1462958.2 | T11: 0 | U11: 1462958.2
A12: 11 | B12: 41241184 | C12: 192433 | D12: 41048751 | E12: 2081.335 | F12: 0 | G12: 2081.335 | H12: 2245.1705 | I12: 0 | J12: 2245.1705 | K12: 478927.43 | L12: 443978.94 | M12: 499424.2 | N12: 192433 | O12: 180770.06 | P12: 11662.945 | Q12: 1135836.1 | R12: 40105347 | S12: 1433993.5 | T12: 0 | U12: 1433993.5
A13: 12 | B13: 40105347 | C13: 187133.15 | D13: 39918214 | E13: 2070.1235 | F13: 0 | G13: 2070.1235 | H13: 2183.3322 | I13: 0 | J13: 2183.3322 | K13: 465736.42 | L13: 441587.36 | M13: 485548.42 | N13: 187133.15 | O13: 174467.95 | P13: 12665.2 | Q13: 1114268.9 | R13: 38991079 | S13: 1405537.4 | T13: 0 | U13: 1405537.4
... A361: 360 | B361: 0 | C361: 0 | D361: 0 | E361: 0 | F361: 0 | G361: 0 | H361: 0 | I361: 0 | J361: 0 | K361: 0 | L361: 0 | M361: 0 | N361: 0 | O361: 0 | P361: 0 | Q361: 0 | R361: 0 | S361: 0 | T361: 0 | U361: 0

Sheet 2021Y
A1: Period | B1: begUPB | C1: begDelinqUPB | D1: begPerfUPB | E1: deinqPrincipal | F1: prinPaidOnDelinqPrin | G1: prinNotPaidOnDelinqPrin | H1: delinqInterest | I1: intPaidOnDelinqInt | J1: intNotPaidOnDelinqInt | K1: netInterest | L1: actAmort | M1: prepayment | N1: liquidation | O1: loss | P1: recovery | Q1: totalUPBDrop | R1: endUPB | S1: totalCashflowBeforeSvc | T1: svcFee | U1: totalCashflow
A2: 1 | B2: 1.3369645e+08 | C2: 701218.45 | D2: 1.3299523e+08 | E2: 4603.5561 | F2: 0 | G2: 4603.5561 | H2: 7354.3504 | I2: 0 | J2: 7354.3504 | K2: 1394848.5 | L2: 873124.48 | M2: 1324099.2 | N2: 701218.45 | O2: 701218.45 | P2: 0 | Q2: 2898442.1 | R2: 1.30798e+08 | S2: 3592072.2 | T2: 0 | U2: 3592072.2
A3: 2 | B3: 1.30798e+08 | C3: 686016.54 | D3: 1.3011199e+08 | E3: 4580.3176 | F3: 0 | G3: 4580.3176 | H3: 7197.5742 | I3: 0 | J3: 7197.5742 | K3: 1365113.9 | L3: 868717 | M3: 1295248.2 | N3: 686016.54 | O3: 682364.36 | P3: 3652.1794 | Q3: 2849981.7 | R3: 1.2794802e+08 | S3: 3532731.2 | T3: 0 | U3: 3532731.2
A4: 3 | B4: 1.2794802e+08 | C4: 671068.8 | D4: 1.2727695e+08 | E4: 4558.1366 | F4: 0 | G4: 4558.1366 | H4: 7040.6926 | I4: 0 | J4: 7040.6926 | K4: 1335359.2 | L4: 864510.08 | M4: 1266878.2 | N4: 671068.8 | O4: 663843.62 | P4: 7225.1822 | Q4: 2802457.1 | R4: 1.2514557e+08 | S4: 3473972.7 | T4: 0 | U4: 3473972.7
A5: 4 | B5: 1.2514557e+08 | C5: 656370.32 | D5: 1.2448919e+08 | E5: 4536.0571 | F5: 0 | G5: 4536.0571 | H5: 6886.4521 | I5: 0 | J5: 6886.4521 | K5: 1306105.5 | L5: 860322.41 | M5: 1238981.9 | N5: 656370.32 | O5: 645649.99 | P5: 10720.332 | Q5: 2755674.6 | R5: 1.2238989e+08 | S5: 3416130.1 | T5: 0 | U5: 3416130.1
A6: 5 | B6: 1.2238989e+08 | C6: 641917.2 | D6: 1.2174797e+08 | E6: 4514.0849 | F6: 0 | G6: 4514.0849 | H6: 6734.7935 | I6: 0 | J6: 6734.7935 | K6: 1277341.5 | L6: 856155.1 | M6: 1211551.7 | N6: 641917.2 | O6: 627778.28 | P6: 14138.928 | Q6: 2709624 | R6: 1.1968027e+08 | S6: 3359187.2 | T6: 0 | U6: 3359187.2
A7: 6 | B7: 1.1968027e+08 | C7: 627705.62 | D7: 1.1905256e+08 | E7: 4492.2254 | F7: 0 | G7: 4492.2254 | H7: 6585.6594 | I7: 0 | J7: 6585.6594 | K7: 1249056.2 | L7: 852009.17 | M7: 1184580.4 | N7: 627705.62 | O7: 610223.37 | P7: 17482.246 | Q7: 2664295.2 | R7: 1.1701597e+08 | S7: 3303128.1 | T7: 0 | U7: 3303128.1
A8: 7 | B8: 1.1701597e+08 | C8: 613731.78 | D8: 1.1640224e+08 | E8: 4470.4671 | F8: 0 | G8: 4470.4671 | H8: 6439.0423 | I8: 0 | J8: 6439.0423 | K8: 1221248.4 | L8: 847882.41 | M8: 1158060.8 | N8: 613731.78 | O8: 592980.23 | P8: 20751.546 | Q8: 2619675 | R8: 1.143963e+08 | S8: 3247943.1 | T8: 0 | U8: 3247943.1
A9: 8 | B9: 1.143963e+08 | C9: 599991.96 | D9: 1.137963e+08 | E9: 4448.8241 | F9: 0 | G9: 4448.8241 | H9: 6294.8604 | I9: 0 | J9: 6294.8604 | K9: 1193902.4 | L9: 843777.54 | M9: 1131985.8 | N9: 599991.96 | O9: 576043.9 | P9: 23948.066 | Q9: 2575755.3 | R9: 1.1182054e+08 | S9: 3193613.8 | T9: 0 | U9: 3193613.8
A10: 9 | B10: 1.1182054e+08 | C10: 586482.5 | D10: 1.1123406e+08 | E10: 4427.2855 | F10: 0 | G10: 4427.2855 | H10: 6153.1057 | I10: 0 | J10: 6153.1057 | K10: 1167016.8 | L10: 839692.47 | M10: 1106348.5 | N10: 586482.5 | O10: 559409.48 | P10: 27073.024 | Q10: 2532523.5 | R10: 1.0928802e+08 | S10: 3140130.8 | T10: 0 | U10: 3140130.8
A11: 10 | B11: 1.0928802e+08 | C11: 573199.78 | D11: 1.0871482e+08 | E11: 4405.8461 | F11: 0 | G11: 4405.8461 | H11: 6013.7535 | I11: 0 | J11: 6013.7535 | K11: 1140586.8 | L11: 835626.21 | M11: 1081141.9 | N11: 573199.78 | O11: 543072.16 | P11: 30127.621 | Q11: 2489967.9 | R11: 1.0679805e+08 | S11: 3087482.6 | T11: 0 | U11: 3087482.6
A12: 11 | B12: 1.0679805e+08 | C12: 560140.26 | D12: 1.0623791e+08 | E12: 4384.517 | F12: 0 | G12: 4384.517 | H12: 5876.734 | I12: 0 | J12: 5876.734 | K12: 1114599.3 | L12: 831580.85 | M12: 1056359.4 | N12: 560140.26 | O12: 527027.23 | P12: 33113.036 | Q12: 2448080.6 | R12: 1.0434997e+08 | S12: 3035652.6 | T12: 0 | U12: 3035652.6
A13: 12 | B13: 1.0434997e+08 | C13: 547300.44 | D13: 1.0380267e+08 | E13: 4363.2961 | F13: 0 | G13: 4363.2961 | H13: 5742.0146 | I13: 0 | J13: 5742.0146 | K13: 1089048 | L13: 827556.03 | M13: 1031994.3 | N13: 547300.44 | O13: 511270 | P13: 36030.433 | Q13: 2406850.8 | R13: 1.0194312e+08 | S13: 2984628.8 | T13: 0 | U13: 2984628.8
... A361: 360 | B361: 0 | C361: 0 | D361: 0 | E361: 0 | F361: 0 | G361: 0 | H361: 0 | I361: 0 | J361: 0 | K361: 0 | L361: 0 | M361: 0 | N361: 0 | O361: 0 | P361: 0 | Q361: 0 | R361: 0 | S361: 0 | T361: 0 | U361: 0

Sheet 2022Q1
A1: Period | B1: begUPB | C1: begDelinqUPB | D1: begPerfUPB | E1: deinqPrincipal | F1: prinPaidOnDelinqPrin | G1: prinNotPaidOnDelinqPrin | H1: delinqInterest | I1: intPaidOnDelinqInt | J1: intNotPaidOnDelinqInt | K1: netInterest | L1: actAmort | M1: prepayment | N1: liquidation | O1: loss | P1: recovery | Q1: totalUPBDrop | R1: endUPB | S1: totalCashflowBeforeSvc | T1: svcFee | U1: totalCashflow
A2: 1 | B2: 42691186 | C2: 247759.67 | D2: 42443426 | E2: 1420.2816 | F2: 0 | G2: 1420.2816 | H2: 2700.8453 | I2: 0 | J2: 2700.8453 | K2: 462678.72 | L2: 243306.82 | M2: 336093.66 | N2: 247759.67 | O2: 247759.67 | P2: 0 | Q2: 827160.16 | R2: 41864026 | S2: 1042079.2 | T2: 0 | U2: 1042079.2
A3: 2 | B3: 41864026 | C3: 242959.22 | D3: 41621067 | E3: 1415.8051 | F3: 0 | G3: 1415.8051 | H3: 2649.4576 | I3: 0 | J3: 2649.4576 | K3: 453875.56 | L3: 242539.95 | M3: 329550.27 | N3: 242959.22 | O3: 241668.81 | P3: 1290.415 | Q3: 815049.44 | R3: 41048976 | S3: 1027256.2 | T3: 0 | U3: 1027256.2
A4: 3 | B4: 41048976 | C4: 238229.06 | D4: 40810747 | E4: 1411.6598 | F4: 0 | G4: 1411.6598 | H4: 2597.8568 | I4: 0 | J4: 2597.8568 | K4: 445035.88 | L4: 241829.83 | M4: 323102.31 | N4: 238229.06 | O4: 235673.23 | P4: 2555.8276 | Q4: 803161.19 | R4: 40245815 | S4: 1012523.8 | T4: 0 | U4: 1012523.8
A5: 4 | B5: 40245815 | C5: 233567.89 | D5: 40012247 | E5: 1407.5245 | F5: 0 | G5: 1407.5245 | H5: 2547.0176 | I5: 0 | J5: 2547.0176 | K5: 436326.67 | L5: 241121.41 | M5: 316748.47 | N5: 233567.89 | O5: 229771.28 | P5: 3796.6039 | Q5: 791437.77 | R5: 39454378 | S5: 997993.15 | T5: 0 | U5: 997993.15
